Workbook

Sheet Dashboard
A1: 🃏 POKÉMON CARD BUSINESS
A3: SALES SUMMARY
A4: Metric | B4: Value
A5: Total Buy Price | B5: =IFERROR(SUM('All-Time Sold'!C3:C999),0) -> 12563.8
A6: Total Sold Price | B6: =IFERROR(SUM('All-Time Sold'!D3:D999),0) -> 25877.46
A7: Total Profit | B7: =IFERROR(SUM('All-Time Sold'!E3:E999),0) -> 13313.66
A8: Cards Sold | B8: =IFERROR(COUNTA('All-Time Sold'!A3:A999),0) -> 18
A10: INVENTORY
A11: Type | B11: # Cards | C11: Total Cost
A12: Slabs | B12: =COUNTA('Slabs Inventory'!A3:A999) -> 19 | C12: =IFERROR(SUM('Slabs Inventory'!C3:C999),0) -> 167.5
A13: Raw | B13: =COUNTA('Raw Inventory'!A3:A1000) -> 47 | C13: =IFERROR(SUM('Raw Inventory'!C3:C1000),0) -> 4148
A14: Total | B14: =B12+B13 -> 66 | C14: =C12+C13 -> 4315.5
A16: PROFIT SPLIT
A17: Person | B17: Split % | C17: Profit Owed
A18: Boss | B18: 1 | C18: =B18*B7 -> 13313.66
A19: Hub | B19: 0 | C19: =B19*B7 -> 0
A20: Tae | B20: 0 | C20: =B20*B7 -> 0

Sheet Slabs Inventory
A1: SLABS INVENTORY (CURRENT)
A2: Card Name | B2: Grade Co. (PSA/BGS/CGC) | C2: Grade | D2: Buy Price ($) | E2: Date Purchased
A3: Mew ex 151 ultra-premium | B3: PSA | C3: 10 | D3: 0 | E3: 46179
A4: Reshiram Charizard gx jp 016 | B4: PSA | C4: 10 | D4: 119 | E4: 46179
A5: Darkrai vstar gg50 | B5: PSA | C5: 10 | D5: 278.8 | E5: 46179
A6: Pokemon xy Dragonite 106 | B6: PSA | C6: 10 | D6: 0 | E6: 46179
A7: Blaziken 192 | B7: PSA | C7: 10 | D7: 148.75 | E7: 46179
A8: deoxys Vmax Crown Zenith gg45 | B8: PSA | C8: 10 | D8: 187 | E8: 46179
A9: Leafeon vstar gg35 | B9: PSA | C9: 10 | D9: 187 | E9: 46179
A10: Mega Gardevoir Ex 178 | B10: PSA | C10: 10 | D10: 0 | E10: 46179
A11: Black Bolt ETB PC Box | B11: N/A | C11: N/A | D11: 300 | E11: 46179
A12: Chinese Gengar 07 | B12: PSA | C12: 10 | D12: 807 | E12: 46179
A13: Chinese Meowth 07 | B13: PSA | C13: 10 | D13: 425 | E13: 46179
A14: Scovillain | B14: PSA | C14: 10 | D14: 34 | E14: 46179
A15: drampa 184 | B15: PSA | C15: 9 | D15: 27 | E15: 46179
A16: Ray V max | B16: PSA | C16: 10 | D16: 80 | E16: 46179
A17: Zamazenta V gg54 | B17: PSA | C17: 10 | D17: 0 | E17: 46179
A18: teal mask ogerpon | B18: CGC | C18: 8.5 | D18: 0 | E18: 46179
A19: Misty's Gyarados | B19: PSA | C19: 10 | D19: 460 | E19: 46188
A20: Tornadus 210 | B20: PSA | C20: 10 | D20: 460 | E20: 46188
A202: TOTALS | D202: =SUM(D3:D201) -> 3513.55

Sheet Raw Inventory
A1: RAW INVENTORY (CURRENT)
A2: Card Name | B2: Condition | C2: Buy Price | D2: Notes
A3: Articuno 2/62 | B3: NM | C3: 33 | D3: LP but list at near mint
A4: Gengar 11/110 | B4: NM | C4: 154
A5: Sceptile ex 96 | B5: LP | C5: 225
A6: Magnemite LC 80/110 | B6: NM | C6: 90
A7: Mewtwo 10 | B7: LP | C7: 33 | D7: LP but push to PSA6 200
A8: Pikachu Shadowless Red Cheeks | B8: NM | C8: 69 | D8: PSA 7 $85 ours much nicer
A9: Sceptile ex 96 | B9: LP | C9: 225
A10: Mewtwo Lv X | B10: LP | C10: 100
A11: Sabrina's Gengar JP | B11: NM | C11: 240
A12: Haunter 027 | B12: NM | C12: 48
A13: Mega charizard x ex 023 | B13: NM | C13: pull
A14: Alonan Exegutor ex 242 | B14: NM | C14: pull
A15: Arven Masbostiff ex 235 | B15: NM | C15: pull
A16: Scolipede 134 | B16: NM | C16: pull
A17: Zebstrika 115 | B17: NM | C17: pull
A18: Bulbasaur 133/132 stamped | B18: NM | C18: 20
A19: Bulbasaur 133/132 | B19: NM | C19: 20
A20: Axew 145/086 | B20: NM | C20: 18.4
A21: N's Reshriam | B21: NM | C21: 18
A22: N's Zoroark ex 189/159 | B22: NM | C22: 14.4
A23: Ampharos 090/086 | B23: NM | C23: 12.8
A24: Hoopa V GG53 | B24: NM | C24: 10.4
A25: Bisharp | B25: NM | C25: pull
A26: Golett | B26: NM | C26: pull
A27: Throh | B27: NM | C27: pull
A28: Zamazenta | B28: NM | C28: pull
A29: TEAM rockets nidoking ex | B29: NM | C29: pull
A30: Treeko | B30: NM | C30: 6
A31: Munchlax | B31: LP | C31: 6
A32: Blaine's charizard jp 006 | B32: LP | C32: 155
A33: Mew southern island promo 01/18 | B33: MP | C33: ?
A34: Charizard gx sm60 | B34: NM | C34: 70 | D34: Traded for umbreon prime DMG price at a loss
A35: shaymin ex rc21 | B35: MP | C35: 17 | D35: Traded for umbreon prime DMG price at a loss
A36: Minun 194 | B36: NM | C36: 50
A37: riolu 215 | B37: NM | C37: 50
A38: Team rockets moltres ex 229 | B38: NM | C38: 118
A39: M charizard ex 13 | B39: NM | C39: 50 | D39: Traded for umbreon prime DMG price at a loss
A40: Gardevoir gx sv75 | B40: NM | C40: 16
...

Sheet All-Time Sold
A1: ALL-TIME SOLD
A2: Card Name | B2: Date Sold | C2: Buy Price ($) | D2: Sold Price ($) | E2: Profit ($)
A3: Eevee | B3: 46179 | C3: 0 | D3: 12 | E3: =IF(D3<>"",D3-C3,"") -> 12
A4: Meowth | B4: 46179 | C4: 0 | D4: 10 | E4: =IF(D4<>"",D4-C4,"") -> 10
A5: 9 Meowth and oricorio ex (2 cards) | B5: 46179 | C5: 30 | D5: 65 | E5: =IF(D5<>"",D5-C5,"") -> 35
A6: garchomp&giratina tag | B6: 46179 | C6: 0 | D6: 480 | E6: =IF(D6<>"",D6-C6,"") -> 480
A7: rocket houndoom | B7: 46179 | C7: 153 | D7: 170 | E7: =IF(D7<>"",D7-C7,"") -> 17
A8: alakazam | B8: 46179 | C8: 297 | D8: 330 | E8: =IF(D8<>"",D8-C8,"") -> 33
A9: Dragonite V volving skies | B9: 46179 | C9: 538 | D9: 1030 | E9: =IF(D9<>"",D9-C9,"") -> 492
A10: Detetive pikachu japenese pre order | B10: 46179 | C10: 416.4 | D10: 500 | E10: =IF(D10<>"",D10-C10,"") -> 83.6
A11: SV2a JP Charmandar | B11: 46179 | C11: 140 | D11: 200 | E11: =IF(D11<>"",D11-C11,"") -> 60
A12: Zekrom ex special Illustration rare | B12: 46179 | C12: 467.5 | D12: 630 | E12: =IF(D12<>"",D12-C12,"") -> 162.5
E13: =IF(D13<>"",D13-C13,"") | F13: =SUM(E3:E12) -> 1385.1
A14: Umbreon | B14: 46180 | C14: 3695 | D14: 4140 | E14: =IF(D14<>"",D14-C14,"") -> 445
A15: Sylveon | B15: 46180 | C15: 0 | D15: 4765 | E15: =IF(D15<>"",D15-C15,"") -> 4765
A16: reshiram and zekrom tag | B16: 46180 | C16: 0 | E16: =IF(D16<>"",D16-C16,"")
A17: Mega Lopunny & Jigglypuff | B17: 46180 | C17: 0 | E17: =IF(D17<>"",D17-C17,"")
A18: mega evo ascended heros box | B18: 46179 | C18: 65 | D18: 65 | E18: =IF(D18<>"",D18-C18,"") -> 0
A19: Dialga Lv X 122 | B19: 46182 | C19: 80 | D19: 120 | E19: =IF(D19<>"",D19-C19,"") -> 40
A20: Charizard ex 199 PSA 9 | B20: 46185 | C20: 400 | D20: 421.73 | E20: =IF(D20<>"",D20-C20,"") -> 21.73
E22: =IF(D22<>"",D22-C22,"")
E23: =IF(D23<>"",D23-C23,"")
E24: =IF(D24<>"",D24-C24,"")
E25: =IF(D25<>"",D25-C25,"")
E26: =IF(D26<>"",D26-C26,"")
E27: =IF(D27<>"",D27-C27,"")
E28: =IF(D28<>"",D28-C28,"")
E29: =IF(D29<>"",D29-C29,"")
E30: =IF(D30<>"",D30-C30,"")
E31: =IF(D31<>"",D31-C31,"")
E32: =IF(D32<>"",D32-C32,"")
E33: =IF(D33<>"",D33-C33,"")
... E201: =IF(D201<>"",D201-C201,"")
A202: TOTALS | C202: =SUM(C3:C201) -> 6281.9 | D202: =SUM(D3:D201) -> 12938.73 | E202: =SUM(E3:E201) -> 6656.83

Sheet Profit Tracking
A1: PROFIT TRACKING
A2: MONTHLY SUMMARY (2026) | F2: PER SHOW LOG | G2: Date | H2: Buy Price ($) | I2: Sold Price ($) | J2: Profit ($)
A3: Month | B3: Buy Price ($) | C3: Sold Price ($) | D3: Profit ($) | F3: Show Name | G3: Date | H3: Show cost | I3: Sold Price ($) | J3: Profit ($)
A4: Jan | B4: =SUMPRODUCT((MONTH('All-Time Sold'!B3:B999)=1)*(YEAR('All-Time Sold'!B3:B999)=YEAR(TODAY()))*'All-Time Sold'!C3:C999) -> 0 | C4: =SUMPRODUCT((MONTH('All-Time Sold'!B3:B999)=1)*(YEAR('All-Time Sold'!B3:B999)=YEAR(TODAY()))*'All-Time Sold'!D3:D999) -> 0 | D4: =C4-B4 -> 0 | F4: Woodbridge APA | G4: 46173 | H4: 90 | I4: 52340 | J4: 39000
A5: Feb | B5: =SUMPRODUCT((MONTH('All-Time Sold'!B3:B999)=2)*(YEAR('All-Time Sold'!B3:B999)=YEAR(TODAY()))*'All-Time Sold'!C3:C999) -> 0 | C5: =SUMPRODUCT((MONTH('All-Time Sold'!B3:B999)=2)*(YEAR('All-Time Sold'!B3:B999)=YEAR(TODAY()))*'All-Time Sold'!D3:D999) -> 0 | D5: =C5-B5 -> 0 | F5: Woodbridge Mall | G5: 46179 | H5: 150 | I5: 3417 | J5: 1375
A6: Mar | B6: =SUMPRODUCT((MONTH('All-Time Sold'!B3:B999)=3)*(YEAR('All-Time Sold'!B3:B999)=YEAR(TODAY()))*'All-Time Sold'!C3:C999) -> 0 | C6: =SUMPRODUCT((MONTH('All-Time Sold'!B3:B999)=3)*(YEAR('All-Time Sold'!B3:B999)=YEAR(TODAY()))*'All-Time Sold'!D3:D999) -> 0 | D6: =C6-B6 -> 0 | F6: Montclair | G6: 46180 | H6: 0 | I6: 8905 | J6: =I6-M7 -> 5210
A7: Apr | B7: =SUMPRODUCT((MONTH('All-Time Sold'!B3:B999)=4)*(YEAR('All-Time Sold'!B3:B999)=YEAR(TODAY()))*'All-Time Sold'!C3:C999) -> 0 | C7: =SUMPRODUCT((MONTH('All-Time Sold'!B3:B999)=4)*(YEAR('All-Time Sold'!B3:B999)=YEAR(TODAY()))*'All-Time Sold'!D3:D999) -> 0 | D7: =C7-B7 -> 0 | F7: Morristown | G7: 46194 | H7: 125 | J7: =IF(I7<>"",I7-H7,"") | M7: 3695
A8: May | B8: =C8-J4 -> 13340 | C8: 52340 | D8: =C8-B8 -> 39000 | F8: Woodbride APA | G8: 46201 | H8: 150 | J8: =IF(I8<>"",I8-H8,"")
A9: Jun | B9: {=SUMPRODUCT((MONTH('All-Time Sold'!B3:B999)=6)*(YEAR('All-Time Sold'!B3:B999)=YEAR(TODAY()))*'All-Time Sold'!C3:C999)} -> 6281.9 | C9: {=SUMPRODUCT((MONTH('All-Time Sold'!B3:B999)=6)*(YEAR('All-Time Sold'!B3:B999)=YEAR(TODAY()))*'All-Time Sold'!D3:D999)} -> 12938.73 | D9: =C9-B9 -> 6656.83 | J9: =IF(I9<>"",I9-H9,"")
A10: Jul | B10: =SUMPRODUCT((MONTH('All-Time Sold'!B3:B999)=7)*(YEAR('All-Time Sold'!B3:B999)=YEAR(TODAY()))*'All-Time Sold'!C3:C999) -> 0 | C10: =SUMPRODUCT((MONTH('All-Time Sold'!B3:B999)=7)*(YEAR('All-Time Sold'!B3:B999)=YEAR(TODAY()))*'All-Time Sold'!D3:D999) -> 0 | D10: =C10-B10 -> 0 | J10: =IF(I10<>"",I10-H10,"")
A11: Aug | B11: =SUMPRODUCT((MONTH('All-Time Sold'!B3:B999)=8)*(YEAR('All-Time Sold'!B3:B999)=YEAR(TODAY()))*'All-Time Sold'!C3:C999) -> 0 | C11: =SUMPRODUCT((MONTH('All-Time Sold'!B3:B999)=8)*(YEAR('All-Time Sold'!B3:B999)=YEAR(TODAY()))*'All-Time Sold'!D3:D999) -> 0 | D11: =C11-B11 -> 0 | J11: =IF(I11<>"",I11-H11,"")
A12: Sep | B12: =SUMPRODUCT((MONTH('All-Time Sold'!B3:B999)=9)*(YEAR('All-Time Sold'!B3:B999)=YEAR(TODAY()))*'All-Time Sold'!C3:C999) -> 0 | C12: =SUMPRODUCT((MONTH('All-Time Sold'!B3:B999)=9)*(YEAR('All-Time Sold'!B3:B999)=YEAR(TODAY()))*'All-Time Sold'!D3:D999) -> 0 | D12: =C12-B12 -> 0 | J12: =IF(I12<>"",I12-H12,"")
A13: Oct | B13: =SUMPRODUCT((MONTH('All-Time Sold'!B3:B999)=10)*(YEAR('All-Time Sold'!B3:B999)=YEAR(TODAY()))*'All-Time Sold'!C3:C999) -> 0 | C13: =SUMPRODUCT((MONTH('All-Time Sold'!B3:B999)=10)*(YEAR('All-Time Sold'!B3:B999)=YEAR(TODAY()))*'All-Time Sold'!D3:D999) -> 0 | D13: =C13-B13 -> 0 | J13: =IF(I13<>"",I13-H13,"")
A14: Nov | B14: =SUMPRODUCT((MONTH('All-Time Sold'!B3:B999)=11)*(YEAR('All-Time Sold'!B3:B999)=YEAR(TODAY()))*'All-Time Sold'!C3:C999) -> 0 | C14: =SUMPRODUCT((MONTH('All-Time Sold'!B3:B999)=11)*(YEAR('All-Time Sold'!B3:B999)=YEAR(TODAY()))*'All-Time Sold'!D3:D999) -> 0 | D14: =C14-B14 -> 0 | J14: =IF(I14<>"",I14-H14,"")
A15: Dec | B15: =SUMPRODUCT((MONTH('All-Time Sold'!B3:B999)=12)*(YEAR('All-Time Sold'!B3:B999)=YEAR(TODAY()))*'All-Time Sold'!C3:C999) -> 0 | C15: =SUMPRODUCT((MONTH('All-Time Sold'!B3:B999)=12)*(YEAR('All-Time Sold'!B3:B999)=YEAR(TODAY()))*'All-Time Sold'!D3:D999) -> 0 | D15: =C15-B15 -> 0 | J15: =IF(I15<>"",I15-H15,"")
A16: TOTALS | B16: =SUM(B4:B15) -> 19621.9 | C16: =SUM(C4:C15) -> 65278.73 | D16: =SUM(D4:D15) -> 45656.83 | J16: =IF(I16<>"",I16-H16,"")
J17: =IF(I17<>"",I17-H17,"")
J18: =IF(I18<>"",I18-H18,"")
J19: =IF(I19<>"",I19-H19,"")
J20: =IF(I20<>"",I20-H20,"")
J21: =IF(I21<>"",I21-H21,"")
J22: =IF(I22<>"",I22-H22,"")
J23: =IF(I23<>"",I23-H23,"")
J24: =IF(I24<>"",I24-H24,"")
J25: =IF(I25<>"",I25-H25,"")
J26: =IF(I26<>"",I26-H26,"")
J27: =IF(I27<>"",I27-H27,"")
J28: =IF(I28<>"",I28-H28,"")
... J53: =IF(I53<>"",I53-H53,"")
F54: TOTALS | H54: =SUM(H4:H53) -> 515 | I54: =SUM(I4:I53) -> 64662 | J54: =SUM(J4:J53) -> 45585
A56: PROFIT SPLIT
A57: Person | B57: Split % | C57: Profit Owed | D57: Paid Out
A58: Boss | B58: 0.8 | C58: =B58*D16 -> 36525.464 | D58: 0
A59: Hub | B59: 0.1 | C59: =B59*D16 -> 4565.683 | D59: 0
A60: Tae | B60: 0.1 | C60: =B60*D16 -> 4565.683 | D60: 0

Sheet Payroll
A1: PAYROLL
A2: RATES
A3: Person | B3: Hourly Rate | C3: Profit % | D3: Role
A4: Hub | B4: 30 | C4: 0 | D4: Partner
A5: Tae | B5: 40 | C5: 0 | D5: Partner
A6: Aryak | B6: — | C6: 1 | D6: Investor
A7: Vic | B7: 40 | C7: — | D7: Hourly Helper
A9: PAY LOG
A10: Date | B10: Person | C10: Hours | D10: Hourly Pay ($) | E10: Share % | F10: Total ($) | G10: Status | H10: Bonus amount
A11: 46173 | B11: Vic | D11: 25 | F11: 750 | G11: Paid
A12: 46173 | B12: Hub | D12: 20 | E12: 0.1 | F12: 4180 | G12: Paid
A13: 46173 | B13: Tae | D13: 20 | E13: 0.1 | F13: 4080 | G13: Paid
A14: 46179 | B14: Vic | C14: 8 | D14: 50 | E14: 0.1 | F14: 400 | G14: Paid
A15: 46179 | B15: Hub | C15: 12 | D15: 25 | E15: 0.1 | F15: =300+H15 -> 440 | G15: Paid | H15: 140
A16: 46179 | B16: Tae | C16: 12 | D16: 30 | E16: 0.1 | F16: 500 | G16: Paid | H16: 140
A17: 46180 | B17: Tae | C17: 0 | E17: 0.05 | F17: 760 | G17: Paid | H17: 260
A18: 46180 | B18: Hub | C18: 0 | E18: 0.025 | F18: 570 | G18: Paid | H18: 130
A19: 46180 | B19: Vic | C19: 0 | D19: 0 | E19: 0.1 | F19: 520 | G19: Paid
F20: =IF(B20<>"",D20+E20,"")
F21: =IF(B21<>"",D21+E21,"")
F22: =IF(B22<>"",D22+E22,"")
F23: =IF(B23<>"",D23+E23,"")
F24: =IF(B24<>"",D24+E24,"")
F25: =IF(B25<>"",D25+E25,"")
F26: =IF(B26<>"",D26+E26,"")
F27: =IF(B27<>"",D27+E27,"")
F28: =IF(B28<>"",D28+E28,"")
F29: =IF(B29<>"",D29+E29,"")
F30: =IF(B30<>"",D30+E30,"")
F31: =IF(B31<>"",D31+E31,"")
... F110: =IF(B110<>"",D110+E110,"")
A111: TOTALS | D111: =SUM(D11:D110) -> 170 | E111: =SUM(E11:E110) -> 0.675 | F111: =SUM(F11:F110) -> 12200
